Workbook

Sheet Content Calendar
A1: KW | B1: Wochenthema | C1: Webinar Datum | D1: Content-Typ | E1: Titel | F1: Verantwortlich | G1: Status | H1: Fällig am | I1: Veröffentlicht am | J1: Link Quelle | K1: Link veröffentlicht | L1: Anmerkungen
A2: 12 | B2: Schenken ohne Risiken - Was steuerlich wichtig ist | C2: 46100 | D2: Webinar | E2: Schenken ohne Risiken - Was steuerlich wichtig ist | F2: RA Braun | G2: Geplant | H2: 2026-03-19
A3: 12 | B3: Schenken ohne Risiken - Was steuerlich wichtig ist | C3: 46100 | D3: Artikel | E3: Schenkungssteuer Freibeträge 2026: Tabelle und Strategien | F3: Frau Schaffer | G3: Geplant | H3: 2026-03-26 | L3: Di 24.03. Übergabe an Frau Schaffer → Do 26.03. Upload
A4: 12 | B4: Schenken ohne Risiken - Was steuerlich wichtig ist | C4: 46100 | D4: YouTube Short | E4: Steuerfrei schenken: So geht's | F4: Olja | G4: Geplant | H4: 46105
A5: 12 | B5: Schenken ohne Risiken - Was steuerlich wichtig ist | C5: 46100 | D5: Instagram Reel | E5: Steuerfrei schenken: So geht's | F5: Olja | G5: Geplant | H5: 46105
A6: 12 | B6: Schenken ohne Risiken - Was steuerlich wichtig ist | C6: 46100 | D6: LinkedIn Video | E6: Warum ich meine Kanzlei gegründet habe — und was ich heute anders machen würde | F6: Olja | G6: Geplant | H6: 46105
A7: 13 | B7: Erbrecht | C7: 46104 | D7: Artikel | E7: Erbrecht: Was Sie wissen müssen | F7: Frau Schaffer | G7: Geplant | H7: 2026-03-26 | L7: Erster Artikel — Qualitäts-Benchmark beachten | Di 24.03. Übergabe → Do 26.03. Upload
A8: 13 | B8: Erbrecht | C8: 46104 | D8: LinkedIn Video | E8: Mein spannendstes Mandat — und was ich daraus gelernt habe | F8: Olja | G8: Geplant | H8: 46108
A9: 13 | B9: Erbrecht | C9: 46104 | D9: Instagram Reel | E9: Erbrecht in 60 Sekunden | F9: Olja | G9: Geplant | H9: 46108
A10: 13 | B10: Erbrecht | C10: 46104 | D10: YouTube Short | E10: Erbrecht: 3 häufige Fehler | F10: Olja | G10: Geplant | H10: 46108 | L10: Aufnahme mit Herrn Braun
A11: 13 | B11: Erbrecht | C11: 46104 | D11: Newsletter | E11: Monatsrückblick März — Schwerpunkt Erbrecht | F11: Olja | G11: Geplant | H11: 46112 | L11: Monatlich, erscheint Ende März
A12: 13 | B12: Nach mir die Sintflut: Gefahren der gesetzlichen Erbfolge - jeder braucht ein Testament! | C12: 46107 | D12: Webinar | E12: Nach mir die Sintflut: Gefahren der gesetzlichen Erbfolge - jeder braucht ein Testament! | F12: RA Braun | G12: Geplant | H12: 2026-03-26
A13: 16 | B13: Sie fragen, wir antworten! Die häufigsten Fragen – klar beantwortet | C13: 46128 | D13: Webinar | E13: Sie fragen, wir antworten! Die häufigsten Fragen – klar beantwortet | F13: RA Braun | G13: Geplant | H13: 2026-04-16
A14: 16 | B14: Sie fragen, wir antworten! Die häufigsten Fragen – klar beantwortet | C14: 46128 | D14: Artikel | E14: Erbrecht FAQ: Die 10 häufigsten Fragen und Antworten | F14: Frau Schaffer | G14: Geplant | H14: 2026-04-23 | L14: Di 21.04. Übergabe an Frau Schaffer → Do 23.04. Upload
A15: 16 | B15: Sie fragen, wir antworten! Die häufigsten Fragen – klar beantwortet | C15: 46128 | D15: YouTube Short | E15: Die häufigste Erbrecht-Frage — Anwalt antwortet | F15: Olja | G15: Geplant | H15: 46133
A16: 16 | B16: Sie fragen, wir antworten! Die häufigsten Fragen – klar beantwortet | C16: 46128 | D16: Instagram Reel | E16: Die häufigste Erbrecht-Frage — Anwalt antwortet | F16: Olja | G16: Geplant | H16: 46133
A17: 16 | B17: Sie fragen, wir antworten! Die häufigsten Fragen – klar beantwortet | C17: 46128 | D17: LinkedIn Video | E17: Ein Tag als Anwalt für Erbrecht — so sieht mein Alltag wirklich aus | F17: Olja | G17: Geplant | H17: 46133
A18: 17 | B18: Ein Leitfaden für Hinterbliebene: Rechte, Pflichten und nächste Schritte | C18: 46135 | D18: Webinar | E18: Ein Leitfaden für Hinterbliebene: Rechte, Pflichten und nächste Schritte | F18: RA Braun | G18: Geplant | H18: 2026-04-23
A19: 17 | B19: Ein Leitfaden für Hinterbliebene: Rechte, Pflichten und nächste Schritte | C19: 46135 | D19: Artikel | E19: Todesfall: Was Angehörige in den ersten 48 Stunden tun müssen | F19: Frau Schaffer | G19: Geplant | H19: 2026-04-30 | L19: Di 28.04. Übergabe an Frau Schaffer → Do 30.04. Upload
A20: 17 | B20: Ein Leitfaden für Hinterbliebene: Rechte, Pflichten und nächste Schritte | C20: 46135 | D20: YouTube Short | E20: Die ersten Schritte nach einem Todesfall | F20: Olja | G20: Geplant | H20: 46140
A21: 17 | B21: Ein Leitfaden für Hinterbliebene: Rechte, Pflichten und nächste Schritte | C21: 46135 | D21: Instagram Reel | E21: Die ersten Schritte nach einem Todesfall | F21: Olja | G21: Geplant | H21: 46140
A22: 17 | B22: Ein Leitfaden für Hinterbliebene: Rechte, Pflichten und nächste Schritte | C22: 46135 | D22: LinkedIn Video | E22: Meine erste Mitarbeiterin — wie aus einer Idee ein Team wurde | F22: Olja | G22: Geplant | H22: 46140
A23: 18 | B23: Nachlassplanung für moderne Familien - Lösungen für Singles, Unverheiratete und Patchworkfamilien | C23: 46142 | D23: Webinar | E23: Nachlassplanung für moderne Familien - Lösungen für Singles, Unverheiratete und Patchworkfamilien | F23: RA Braun | G23: Geplant | H23: 2026-04-30
A24: 18 | B24: Nachlassplanung für moderne Familien - Lösungen für Singles, Unverheiratete und Patchworkfamilien | C24: 46142 | D24: Artikel | E24: Testament für Patchworkfamilien: Stiefkinder richtig absichern | F24: Frau Schaffer | G24: Geplant | H24: 2026-05-07 | L24: Di 05.05. Übergabe an Frau Schaffer → Do 07.05. Upload
A25: 18 | B25: Nachlassplanung für moderne Familien - Lösungen für Singles, Unverheiratete und Patchworkfamilien | C25: 46142 | D25: YouTube Short | E25: Patchworkfamilie? So muss Ihr Testament aussehen | F25: Olja | G25: Geplant | H25: 46147
A26: 18 | B26: Nachlassplanung für moderne Familien - Lösungen für Singles, Unverheiratete und Patchworkfamilien | C26: 46142 | D26: Instagram Reel | E26: Patchworkfamilie? So muss Ihr Testament aussehen | F26: Olja | G26: Geplant | H26: 46147
A27: 18 | B27: Nachlassplanung für moderne Familien - Lösungen für Singles, Unverheiratete und Patchworkfamilien | C27: 46142 | D27: LinkedIn Video | E27: KI in meiner Kanzlei — was funktioniert und was (noch) nicht | F27: Olja | G27: Geplant | H27: 46147
A28: 19 | B28: Testamente unter Ehegatten richtig gemacht: Typische Irrtümer und die verheerenden Folgen | C28: 46149 | D28: Webinar | E28: Testamente unter Ehegatten richtig gemacht: Typische Irrtümer und die verheerenden Folgen | F28: RA Braun | G28: Geplant | H28: 2026-05-07
A29: 19 | B29: Testamente unter Ehegatten richtig gemacht: Typische Irrtümer und die verheerenden Folgen | C29: 46149 | D29: Artikel | E29: Berliner Testament: Vorteile, Risiken und Alternativen | F29: Frau Schaffer | G29: Geplant | H29: 2026-05-14 | L29: Di 12.05. Übergabe an Frau Schaffer → Do 14.05. Upload
A30: 19 | B30: Testamente unter Ehegatten richtig gemacht: Typische Irrtümer und die verheerenden Folgen | C30: 46149 | D30: YouTube Short | E30: Berliner Testament: Die 3 größten Risiken | F30: Olja | G30: Geplant | H30: 46154
A31: 19 | B31: Testamente unter Ehegatten richtig gemacht: Typische Irrtümer und die verheerenden Folgen | C31: 46149 | D31: Instagram Reel | E31: Berliner Testament: Die 3 größten Risiken | F31: Olja | G31: Geplant | H31: 46154
A32: 19 | B32: Testamente unter Ehegatten richtig gemacht: Typische Irrtümer und die verheerenden Folgen | C32: 46149 | D32: LinkedIn Video | E32: Was mich nach Jahren im Erbrecht immer noch überrascht | F32: Olja | G32: Geplant | H32: 46154
A33: 21 | B33: Das Pflichtteilsrecht: Schutz, Risiko, Stolperfalle? Was Sie wissen müssen | C33: 46163 | D33: Webinar | E33: Das Pflichtteilsrecht: Schutz, Risiko, Stolperfalle? Was Sie wissen müssen | F33: RA Braun | G33: Geplant | H33: 2026-05-21
A34: 21 | B34: Das Pflichtteilsrecht: Schutz, Risiko, Stolperfalle? Was Sie wissen müssen | C34: 46163 | D34: Artikel | E34: Pflichtteil berechnen: Formel, Beispiele und Sonderfälle | F34: Frau Schaffer | G34: Geplant | H34: 2026-05-28 | L34: Di 26.05. Übergabe an Frau Schaffer → Do 28.05. Upload
A35: 21 | B35: Das Pflichtteilsrecht: Schutz, Risiko, Stolperfalle? Was Sie wissen müssen | C35: 46163 | D35: YouTube Short | E35: Pflichtteil berechnen: Einfach erklärt | F35: Olja | G35: Geplant | H35: 46168
A36: 21 | B36: Das Pflichtteilsrecht: Schutz, Risiko, Stolperfalle? Was Sie wissen müssen | C36: 46163 | D36: Instagram Reel | E36: Pflichtteil berechnen: Einfach erklärt | F36: Olja | G36: Geplant | H36: 46168
A37: 21 | B37: Das Pflichtteilsrecht: Schutz, Risiko, Stolperfalle? Was Sie wissen müssen | C37: 46163 | D37: LinkedIn Video | E37: Ein Tag als Testamentsvollstrecker — zwischen Verantwortung und Vertrauen | F37: Olja | G37: Geplant | H37: 46168
A38: 24 | B38: Eine Immobilie - Zwei Kinder: Wie soll ich meinen Nachlass planen? | C38: 46184 | D38: Webinar | E38: Eine Immobilie - Zwei Kinder: Wie soll ich meinen Nachlass planen? | F38: RA Braun | G38: Geplant | H38: 2026-06-11
A39: 24 | B39: Eine Immobilie - Zwei Kinder: Wie soll ich meinen Nachlass planen? | C39: 46184 | D39: Artikel | E39: Immobilie vererben: Steuern, Teilung und Strategien | F39: Frau Schaffer | G39: Geplant | H39: 2026-06-18 | L39: Di 16.06. Übergabe an Frau Schaffer → Do 18.06. Upload
A40: 24 | B40: Eine Immobilie - Zwei Kinder: Wie soll ich meinen Nachlass planen? | C40: 46184 | D40: YouTube Short | E40: Immobilie vererben: Steuerfalle vermeiden | F40: Olja | G40: Geplant | H40: 46189
...

Sheet Performance
A1: KW | B1: Content-Typ | C1: Titel | D1: Veröffentlicht am | E1: Impressions | F1: Clicks | G1: Engagement | H1: CTR (%) | I1: Bemerkung
A2: 13 | B2: Artikel | C2: Erbrecht: Was Sie wissen müssen | H2: =IF(AND(E2<>"",F2<>""),F2/E2*100,"")
A3: 13 | B3: LinkedIn Video | C3: Erbrecht kompakt erklärt | H3: =IF(AND(E3<>"",F3<>""),F3/E3*100,"")
A4: 13 | B4: Instagram Reel | C4: Erbrecht in 60 Sekunden | H4: =IF(AND(E4<>"",F4<>""),F4/E4*100,"")
A5: 13 | B5: YouTube Short | C5: Erbrecht: 3 häufige Fehler | H5: =IF(AND(E5<>"",F5<>""),F5/E5*100,"")
A6: 13 | B6: Newsletter | C6: Monatsrückblick März — Schwerpunkt Erbrecht | H6: =IF(AND(E6<>"",F6<>""),F6/E6*100,"")

Sheet Übersicht
A1: ÜBERSICHT — Content Dashboard
A3: Status-Übersicht | B3: Anzahl | D3: Nächste Deadlines | E3: Datum | F3: Titel
A4: Geplant | B4: =COUNTIF('Content Calendar'!G:G,"Geplant") -> 126 | D4: =IFERROR(__xludf.DUMMYFUNCTION("FILTER('Content Calendar'!H2:H194,'Content Calendar'!G2:G194<>""Veröffentlicht"",'Content Calendar'!H2:H194<>"""")"),"#REF!") -> #REF! | E4: =IFERROR(__xludf.DUMMYFUNCTION("FILTER('Content Calendar'!E2:E194,'Content Calendar'!G2:G194<>""Veröffentlicht"",'Content Calendar'!H2:H194<>"""")"),"#REF!") -> #REF!
A5: In Arbeit | B5: =COUNTIF('Content Calendar'!G:G,"In Arbeit") -> 0
A6: Review | B6: =COUNTIF('Content Calendar'!G:G,"Review") -> 0
A7: Freigegeben | B7: =COUNTIF('Content Calendar'!G:G,"Freigegeben") -> 0
A8: Veröffentlicht | B8: =COUNTIF('Content Calendar'!G:G,"Veröffentlicht") -> 0
A10: Performance pro Kanal | B10: Ø Impressions | C10: Ø Clicks | D10: Ø Engagement | E10: Ø CTR (%)
A11: Artikel | B11: =IFERROR(AVERAGEIF(Performance!B:B,"Artikel",Performance!E:E),"-") -> - | C11: =IFERROR(AVERAGEIF(Performance!B:B,"Artikel",Performance!F:F),"-") -> - | D11: =IFERROR(AVERAGEIF(Performance!B:B,"Artikel",Performance!G:G),"-") -> - | E11: =IFERROR(AVERAGEIF(Performance!B:B,"Artikel",Performance!H:H),"-") -> -
A12: LinkedIn Video | B12: =IFERROR(AVERAGEIF(Performance!B:B,"LinkedIn Video",Performance!E:E),"-") -> - | C12: =IFERROR(AVERAGEIF(Performance!B:B,"LinkedIn Video",Performance!F:F),"-") -> - | D12: =IFERROR(AVERAGEIF(Performance!B:B,"LinkedIn Video",Performance!G:G),"-") -> - | E12: =IFERROR(AVERAGEIF(Performance!B:B,"LinkedIn Video",Performance!H:H),"-") -> -
A13: Instagram Reel | B13: =IFERROR(AVERAGEIF(Performance!B:B,"Instagram Reel",Performance!E:E),"-") -> - | C13: =IFERROR(AVERAGEIF(Performance!B:B,"Instagram Reel",Performance!F:F),"-") -> - | D13: =IFERROR(AVERAGEIF(Performance!B:B,"Instagram Reel",Performance!G:G),"-") -> - | E13: =IFERROR(AVERAGEIF(Performance!B:B,"Instagram Reel",Performance!H:H),"-") -> -
A14: YouTube Short | B14: =IFERROR(AVERAGEIF(Performance!B:B,"YouTube Short",Performance!E:E),"-") -> - | C14: =IFERROR(AVERAGEIF(Performance!B:B,"YouTube Short",Performance!F:F),"-") -> - | D14: =IFERROR(AVERAGEIF(Performance!B:B,"YouTube Short",Performance!G:G),"-") -> - | E14: =IFERROR(AVERAGEIF(Performance!B:B,"YouTube Short",Performance!H:H),"-") -> -
A15: Newsletter | B15: =IFERROR(AVERAGEIF(Performance!B:B,"Newsletter",Performance!E:E),"-") -> - | C15: =IFERROR(AVERAGEIF(Performance!B:B,"Newsletter",Performance!F:F),"-") -> - | D15: =IFERROR(AVERAGEIF(Performance!B:B,"Newsletter",Performance!G:G),"-") -> - | E15: =IFERROR(AVERAGEIF(Performance!B:B,"Newsletter",Performance!H:H),"-") -> -
